<?xml version="1.0" encoding="utf-8"?>
<!-- This URDF was automatically created by SolidWorks to URDF Exporter! Originally created by Stephen Brawner (brawner@gmail.com) 
     Commit Version: 1.6.0-4-g7f85cfe  Build Version: 1.6.7995.38578
     For more information, please see http://wiki.ros.org/sw_urdf_exporter -->
<robot
  name="omniwheel">
  <link
    name="center_link">
    <inertial>
      <origin
        xyz="-1.7913E-18 3.2929E-19 1.715E-17"
        rpy="0 0 0" />
      <mass
        value="0.08478" />
      <inertia
        ixx="1.5E-05"
        ixy="-2.788E-23"
        ixz="2.3372E-20"
        iyy="2.4349E-05"
        iyz="1.3086E-24"
        izz="1.5E-05" />
    </inertial>
    <visual>
      <origin
        xyz="0 0 0"
        rpy="0 0 0" />
      <geometry>
        <mesh
          filename="../meshes/center_link.STL" />
      </geometry>
      <material
        name="">
        <color
          rgba="0.89804 0.91765 0.92941 1" />
      </material>
    </visual>
    <collision>
      <origin
        xyz="0 0 0"
        rpy="0 0 0" />
      <geometry>
        <mesh
          filename="../meshes/center_link.STL" />
      </geometry>
    </collision>
  </link>
  <link
    name="roller_link_0">
    <inertial>
      <origin
        xyz="-5.5511E-17 -6.9389E-18 3.8164E-17"
        rpy="0 0 0" />
      <mass
        value="0.06464" />
      <inertia
        ixx="1.7875E-05"
        ixy="3.1764E-22"
        ixz="7.889E-06"
        iyy="2.5764E-05"
        iyz="-2.9646E-21"
        izz="1.7875E-05" />
    </inertial>
    <visual>
      <origin
        xyz="0 0 0"
        rpy="0 0 0" />
      <geometry>
        <mesh
          filename="../meshes/roller_link_0.STL" />
      </geometry>
      <material
        name="">
        <color
          rgba="0.29804 0.29804 0.29804 1" />
      </material>
    </visual>
    <collision>
      <origin
        xyz="0 0 0"
        rpy="0 0 0" />
      <geometry>
        <mesh
          filename="../meshes/roller_link_0.STL" />
      </geometry>
    </collision>
  </link>
  <joint
    name="roller_joint_0"
    type="revolute">
    <origin
      xyz="0.030052 -0.030052 0"
      rpy="1.8823 0.29744 -3.0945" />
    <parent
      link="center_link" />
    <child
      link="roller_link_0" />
    <axis
      xyz="0.70711 0 -0.70711" />
    <limit
      effort="10000"
      velocity="1000" />
    <dynamics
      damping="0"
      friction="0" />
  </joint>
  <link
    name="roller_link_1">
    <inertial>
      <origin
        xyz="-5.5511E-17 7.0183E-38 -2.0817E-17"
        rpy="0 0 0" />
      <mass
        value="0.06464" />
      <inertia
        ixx="1.7875E-05"
        ixy="-1.0848E-40"
        ixz="-7.889E-06"
        iyy="2.5764E-05"
        iyz="-1.147E-40"
        izz="1.7875E-05" />
    </inertial>
    <visual>
      <origin
        xyz="0 0 0"
        rpy="0 0 0" />
      <geometry>
        <mesh
          filename="../meshes/roller_link_1.STL" />
      </geometry>
      <material
        name="">
        <color
          rgba="0.29804 0.29804 0.29804 1" />
      </material>
    </visual>
    <collision>
      <origin
        xyz="0 0 0"
        rpy="0 0 0" />
      <geometry>
        <mesh
          filename="../meshes/roller_link_1.STL" />
      </geometry>
    </collision>
  </link>
  <joint
    name="roller_joint_1"
    type="revolute">
    <origin
      xyz="0.030052 0.030052 0"
      rpy="-1.5708 0 -1.5708" />
    <parent
      link="center_link" />
    <child
      link="roller_link_1" />
    <axis
      xyz="0.70711 0 0.70711" />
    <limit
      effort="10000"
      velocity="1000" />
    <dynamics
      damping="0"
      friction="0" />
  </joint>
  <link
    name="roller_link_2">
    <inertial>
      <origin
        xyz="-2.6368E-16 -7.0183E-38 2.3939E-16"
        rpy="0 0 0" />
      <mass
        value="0.06464" />
      <inertia
        ixx="1.7875E-05"
        ixy="1.0848E-40"
        ixz="7.889E-06"
        iyy="2.5764E-05"
        iyz="-1.147E-40"
        izz="1.7875E-05" />
    </inertial>
    <visual>
      <origin
        xyz="0 0 0"
        rpy="0 0 0" />
      <geometry>
        <mesh
          filename="../meshes/roller_link_2.STL" />
      </geometry>
      <material
        name="">
        <color
          rgba="0.29804 0.29804 0.29804 1" />
      </material>
    </visual>
    <collision>
      <origin
        xyz="0 0 0"
        rpy="0 0 0" />
      <geometry>
        <mesh
          filename="../meshes/roller_link_2.STL" />
      </geometry>
    </collision>
  </link>
  <joint
    name="roller_joint_2"
    type="revolute">
    <origin
      xyz="-0.030052 0.030052 0"
      rpy="1.5708 0 0" />
    <parent
      link="center_link" />
    <child
      link="roller_link_2" />
    <axis
      xyz="0.70711 0 -0.70711" />
    <limit
      effort="10000"
      velocity="1000" />
    <dynamics
      damping="0"
      friction="0" />
  </joint>
  <link
    name="roller_link_3">
    <inertial>
      <origin
        xyz="-1.3878E-17 -1.7347E-18 1.3878E-17"
        rpy="0 0 0" />
      <mass
        value="0.06464" />
      <inertia
        ixx="1.7875E-05"
        ixy="-1.4823E-21"
        ixz="7.889E-06"
        iyy="2.5764E-05"
        iyz="3.3087E-24"
        izz="1.7875E-05" />
    </inertial>
    <visual>
      <origin
        xyz="0 0 0"
        rpy="0 0 0" />
      <geometry>
        <mesh
          filename="../meshes/roller_link_3.STL" />
      </geometry>
      <material
        name="">
        <color
          rgba="0.29804 0.29804 0.29804 1" />
      </material>
    </visual>
    <collision>
      <origin
        xyz="0 0 0"
        rpy="0 0 0" />
      <geometry>
        <mesh
          filename="../meshes/roller_link_3.STL" />
      </geometry>
    </collision>
  </link>
  <joint
    name="roller_joint_3"
    type="revolute">
    <origin
      xyz="-0.030052 -0.030052 0"
      rpy="1.4212 -0.14796 1.5819" />
    <parent
      link="center_link" />
    <child
      link="roller_link_3" />
    <axis
      xyz="0.70711 0 -0.70711" />
    <limit
      effort="10000"
      velocity="1000" />
    <dynamics
      damping="0"
      friction="0" />
  </joint>
</robot>